Workbook

Sheet Summary
A1: ServSafe Manager (9th edition) practice question bank
B2: Every question from the class materials, one row each on the Questions sheet: question, all answer choices, correct answer,
B3: chapter (1–10) and what it tests. Use the filter arrows on row 1 to pick a chapter or source.
B4: Yellow rows: the source gives no answer, so one was assigned from ServSafe Manager 9th ed. / FDA Food Code rules
B5: (the Explanation column gives the rule). They are also listed on the Assigned answers sheet.
B6: Pink rows: the question depends on a picture that isn’t in the file, so it can’t be answered. Kept for completeness only.
B7: To quiz yourself, hide columns J–M (Correct answer, Answer from, Explanation, What it tests).
B8: The website is multiple choice only: column O shows how each question appears there, and the Website rewrites sheet
B9: shows true/false, select-all, put-in-order and fill-in questions next to their multiple-choice versions.
A11: Chapter | B11: Chapter name | C11: Kahoot Ch 4-6 | D11: SSM9E Activity Quiz 1 | E11: SSM9E Activity Quiz 2 | F11: SSM9E Activity Quiz 3 | G11: SSM9E Activity Quiz 4 | H11: SSM9E Activity Quiz 5 | I11: SSM9E Activity Quiz 6 | J11: SSM9E Activity Quiz 7 | K11: SSM9E Activity Quiz 8 | L11: SSM9E Activity Quiz 9 | M11: SSM9E Activity Quiz 10 | N11: Practice Test | O11: Diagnostic Test | P11: Mock ServSafe Test | Q11: Review Slide Deck | R11: Total | S11: Assigned answers
A12: 1 | B12: Providing Safe Food | C12: =COUNTIFS(Questions!$D$2:$D$458,$A12,Questions!$B$2:$B$458,C$11) -> 0 | D12: =COUNTIFS(Questions!$D$2:$D$458,$A12,Questions!$B$2:$B$458,D$11) -> 11 | E12: =COUNTIFS(Questions!$D$2:$D$458,$A12,Questions!$B$2:$B$458,E$11) -> 0 | F12: =COUNTIFS(Questions!$D$2:$D$458,$A12,Questions!$B$2:$B$458,F$11) -> 0 | G12: =COUNTIFS(Questions!$D$2:$D$458,$A12,Questions!$B$2:$B$458,G$11) -> 0 | H12: =COUNTIFS(Questions!$D$2:$D$458,$A12,Questions!$B$2:$B$458,H$11) -> 0 | I12: =COUNTIFS(Questions!$D$2:$D$458,$A12,Questions!$B$2:$B$458,I$11) -> 0 | J12: =COUNTIFS(Questions!$D$2:$D$458,$A12,Questions!$B$2:$B$458,J$11) -> 0 | ... Q12: =COUNTIFS(Questions!$D$2:$D$458,$A12,Questions!$B$2:$B$458,Q$11) -> 5 | R12: =SUM(C12:Q12) -> 21 | S12: =COUNTIFS(Questions!$D$2:$D$458,$A12,Questions!$K$2:$K$458,"Assigned*") -> 3
A13: 2 | B13: Forms of Contamination | C13: =COUNTIFS(Questions!$D$2:$D$458,$A13,Questions!$B$2:$B$458,C$11) -> 0 | D13: =COUNTIFS(Questions!$D$2:$D$458,$A13,Questions!$B$2:$B$458,D$11) -> 0 | E13: =COUNTIFS(Questions!$D$2:$D$458,$A13,Questions!$B$2:$B$458,E$11) -> 14 | F13: =COUNTIFS(Questions!$D$2:$D$458,$A13,Questions!$B$2:$B$458,F$11) -> 0 | G13: =COUNTIFS(Questions!$D$2:$D$458,$A13,Questions!$B$2:$B$458,G$11) -> 0 | H13: =COUNTIFS(Questions!$D$2:$D$458,$A13,Questions!$B$2:$B$458,H$11) -> 0 | I13: =COUNTIFS(Questions!$D$2:$D$458,$A13,Questions!$B$2:$B$458,I$11) -> 0 | J13: =COUNTIFS(Questions!$D$2:$D$458,$A13,Questions!$B$2:$B$458,J$11) -> 0 | ... Q13: =COUNTIFS(Questions!$D$2:$D$458,$A13,Questions!$B$2:$B$458,Q$11) -> 17 | R13: =SUM(C13:Q13) -> 48 | S13: =COUNTIFS(Questions!$D$2:$D$458,$A13,Questions!$K$2:$K$458,"Assigned*") -> 4
A14: 3 | B14: The Safe Food Handler | C14: =COUNTIFS(Questions!$D$2:$D$458,$A14,Questions!$B$2:$B$458,C$11) -> 0 | D14: =COUNTIFS(Questions!$D$2:$D$458,$A14,Questions!$B$2:$B$458,D$11) -> 0 | E14: =COUNTIFS(Questions!$D$2:$D$458,$A14,Questions!$B$2:$B$458,E$11) -> 0 | F14: =COUNTIFS(Questions!$D$2:$D$458,$A14,Questions!$B$2:$B$458,F$11) -> 11 | G14: =COUNTIFS(Questions!$D$2:$D$458,$A14,Questions!$B$2:$B$458,G$11) -> 0 | H14: =COUNTIFS(Questions!$D$2:$D$458,$A14,Questions!$B$2:$B$458,H$11) -> 0 | I14: =COUNTIFS(Questions!$D$2:$D$458,$A14,Questions!$B$2:$B$458,I$11) -> 0 | J14: =COUNTIFS(Questions!$D$2:$D$458,$A14,Questions!$B$2:$B$458,J$11) -> 0 | ... Q14: =COUNTIFS(Questions!$D$2:$D$458,$A14,Questions!$B$2:$B$458,Q$11) -> 19 | R14: =SUM(C14:Q14) -> 50 | S14: =COUNTIFS(Questions!$D$2:$D$458,$A14,Questions!$K$2:$K$458,"Assigned*") -> 11
A15: 4 | B15: The Flow of Food: An Introduction | C15: =COUNTIFS(Questions!$D$2:$D$458,$A15,Questions!$B$2:$B$458,C$11) -> 6 | D15: =COUNTIFS(Questions!$D$2:$D$458,$A15,Questions!$B$2:$B$458,D$11) -> 0 | E15: =COUNTIFS(Questions!$D$2:$D$458,$A15,Questions!$B$2:$B$458,E$11) -> 0 | F15: =COUNTIFS(Questions!$D$2:$D$458,$A15,Questions!$B$2:$B$458,F$11) -> 0 | G15: =COUNTIFS(Questions!$D$2:$D$458,$A15,Questions!$B$2:$B$458,G$11) -> 11 | H15: =COUNTIFS(Questions!$D$2:$D$458,$A15,Questions!$B$2:$B$458,H$11) -> 0 | I15: =COUNTIFS(Questions!$D$2:$D$458,$A15,Questions!$B$2:$B$458,I$11) -> 0 | J15: =COUNTIFS(Questions!$D$2:$D$458,$A15,Questions!$B$2:$B$458,J$11) -> 0 | ... Q15: =COUNTIFS(Questions!$D$2:$D$458,$A15,Questions!$B$2:$B$458,Q$11) -> 13 | R15: =SUM(C15:Q15) -> 34 | S15: =COUNTIFS(Questions!$D$2:$D$458,$A15,Questions!$K$2:$K$458,"Assigned*") -> 6
A16: 5 | B16: The Flow of Food: Purchasing, Receiving, and Storage | C16: =COUNTIFS(Questions!$D$2:$D$458,$A16,Questions!$B$2:$B$458,C$11) -> 7 | D16: =COUNTIFS(Questions!$D$2:$D$458,$A16,Questions!$B$2:$B$458,D$11) -> 0 | E16: =COUNTIFS(Questions!$D$2:$D$458,$A16,Questions!$B$2:$B$458,E$11) -> 0 | F16: =COUNTIFS(Questions!$D$2:$D$458,$A16,Questions!$B$2:$B$458,F$11) -> 0 | G16: =COUNTIFS(Questions!$D$2:$D$458,$A16,Questions!$B$2:$B$458,G$11) -> 0 | H16: =COUNTIFS(Questions!$D$2:$D$458,$A16,Questions!$B$2:$B$458,H$11) -> 12 | I16: =COUNTIFS(Questions!$D$2:$D$458,$A16,Questions!$B$2:$B$458,I$11) -> 0 | J16: =COUNTIFS(Questions!$D$2:$D$458,$A16,Questions!$B$2:$B$458,J$11) -> 0 | ... Q16: =COUNTIFS(Questions!$D$2:$D$458,$A16,Questions!$B$2:$B$458,Q$11) -> 33 | R16: =SUM(C16:Q16) -> 76 | S16: =COUNTIFS(Questions!$D$2:$D$458,$A16,Questions!$K$2:$K$458,"Assigned*") -> 5
A17: 6 | B17: The Flow of Food: Preparation | C17: =COUNTIFS(Questions!$D$2:$D$458,$A17,Questions!$B$2:$B$458,C$11) -> 11 | D17: =COUNTIFS(Questions!$D$2:$D$458,$A17,Questions!$B$2:$B$458,D$11) -> 0 | E17: =COUNTIFS(Questions!$D$2:$D$458,$A17,Questions!$B$2:$B$458,E$11) -> 0 | F17: =COUNTIFS(Questions!$D$2:$D$458,$A17,Questions!$B$2:$B$458,F$11) -> 0 | G17: =COUNTIFS(Questions!$D$2:$D$458,$A17,Questions!$B$2:$B$458,G$11) -> 0 | H17: =COUNTIFS(Questions!$D$2:$D$458,$A17,Questions!$B$2:$B$458,H$11) -> 0 | I17: =COUNTIFS(Questions!$D$2:$D$458,$A17,Questions!$B$2:$B$458,I$11) -> 12 | J17: =COUNTIFS(Questions!$D$2:$D$458,$A17,Questions!$B$2:$B$458,J$11) -> 0 | ... Q17: =COUNTIFS(Questions!$D$2:$D$458,$A17,Questions!$B$2:$B$458,Q$11) -> 8 | R17: =SUM(C17:Q17) -> 55 | S17: =COUNTIFS(Questions!$D$2:$D$458,$A17,Questions!$K$2:$K$458,"Assigned*") -> 3
A18: 7 | B18: The Flow of Food: Service | C18: =COUNTIFS(Questions!$D$2:$D$458,$A18,Questions!$B$2:$B$458,C$11) -> 0 | D18: =COUNTIFS(Questions!$D$2:$D$458,$A18,Questions!$B$2:$B$458,D$11) -> 0 | E18: =COUNTIFS(Questions!$D$2:$D$458,$A18,Questions!$B$2:$B$458,E$11) -> 0 | F18: =COUNTIFS(Questions!$D$2:$D$458,$A18,Questions!$B$2:$B$458,F$11) -> 0 | G18: =COUNTIFS(Questions!$D$2:$D$458,$A18,Questions!$B$2:$B$458,G$11) -> 0 | H18: =COUNTIFS(Questions!$D$2:$D$458,$A18,Questions!$B$2:$B$458,H$11) -> 0 | I18: =COUNTIFS(Questions!$D$2:$D$458,$A18,Questions!$B$2:$B$458,I$11) -> 0 | J18: =COUNTIFS(Questions!$D$2:$D$458,$A18,Questions!$B$2:$B$458,J$11) -> 11 | ... Q18: =COUNTIFS(Questions!$D$2:$D$458,$A18,Questions!$B$2:$B$458,Q$11) -> 10 | R18: =SUM(C18:Q18) -> 36 | S18: =COUNTIFS(Questions!$D$2:$D$458,$A18,Questions!$K$2:$K$458,"Assigned*") -> 4
A19: 8 | B19: Food Safety Management Systems | C19: =COUNTIFS(Questions!$D$2:$D$458,$A19,Questions!$B$2:$B$458,C$11) -> 0 | D19: =COUNTIFS(Questions!$D$2:$D$458,$A19,Questions!$B$2:$B$458,D$11) -> 0 | E19: =COUNTIFS(Questions!$D$2:$D$458,$A19,Questions!$B$2:$B$458,E$11) -> 0 | F19: =COUNTIFS(Questions!$D$2:$D$458,$A19,Questions!$B$2:$B$458,F$11) -> 0 | G19: =COUNTIFS(Questions!$D$2:$D$458,$A19,Questions!$B$2:$B$458,G$11) -> 0 | H19: =COUNTIFS(Questions!$D$2:$D$458,$A19,Questions!$B$2:$B$458,H$11) -> 0 | I19: =COUNTIFS(Questions!$D$2:$D$458,$A19,Questions!$B$2:$B$458,I$11) -> 0 | J19: =COUNTIFS(Questions!$D$2:$D$458,$A19,Questions!$B$2:$B$458,J$11) -> 0 | ... Q19: =COUNTIFS(Questions!$D$2:$D$458,$A19,Questions!$B$2:$B$458,Q$11) -> 5 | R19: =SUM(C19:Q19) -> 26 | S19: =COUNTIFS(Questions!$D$2:$D$458,$A19,Questions!$K$2:$K$458,"Assigned*") -> 1
A20: 9 | B20: Safe Facilities and Pest Management | C20: =COUNTIFS(Questions!$D$2:$D$458,$A20,Questions!$B$2:$B$458,C$11) -> 0 | D20: =COUNTIFS(Questions!$D$2:$D$458,$A20,Questions!$B$2:$B$458,D$11) -> 0 | E20: =COUNTIFS(Questions!$D$2:$D$458,$A20,Questions!$B$2:$B$458,E$11) -> 0 | F20: =COUNTIFS(Questions!$D$2:$D$458,$A20,Questions!$B$2:$B$458,F$11) -> 0 | G20: =COUNTIFS(Questions!$D$2:$D$458,$A20,Questions!$B$2:$B$458,G$11) -> 0 | H20: =COUNTIFS(Questions!$D$2:$D$458,$A20,Questions!$B$2:$B$458,H$11) -> 0 | I20: =COUNTIFS(Questions!$D$2:$D$458,$A20,Questions!$B$2:$B$458,I$11) -> 0 | J20: =COUNTIFS(Questions!$D$2:$D$458,$A20,Questions!$B$2:$B$458,J$11) -> 0 | ... Q20: =COUNTIFS(Questions!$D$2:$D$458,$A20,Questions!$B$2:$B$458,Q$11) -> 18 | R20: =SUM(C20:Q20) -> 59 | S20: =COUNTIFS(Questions!$D$2:$D$458,$A20,Questions!$K$2:$K$458,"Assigned*") -> 4
A21: 10 | B21: Cleaning and Sanitizing | C21: =COUNTIFS(Questions!$D$2:$D$458,$A21,Questions!$B$2:$B$458,C$11) -> 0 | D21: =COUNTIFS(Questions!$D$2:$D$458,$A21,Questions!$B$2:$B$458,D$11) -> 0 | E21: =COUNTIFS(Questions!$D$2:$D$458,$A21,Questions!$B$2:$B$458,E$11) -> 0 | F21: =COUNTIFS(Questions!$D$2:$D$458,$A21,Questions!$B$2:$B$458,F$11) -> 0 | G21: =COUNTIFS(Questions!$D$2:$D$458,$A21,Questions!$B$2:$B$458,G$11) -> 0 | H21: =COUNTIFS(Questions!$D$2:$D$458,$A21,Questions!$B$2:$B$458,H$11) -> 0 | I21: =COUNTIFS(Questions!$D$2:$D$458,$A21,Questions!$B$2:$B$458,I$11) -> 0 | J21: =COUNTIFS(Questions!$D$2:$D$458,$A21,Questions!$B$2:$B$458,J$11) -> 0 | ... Q21: =COUNTIFS(Questions!$D$2:$D$458,$A21,Questions!$B$2:$B$458,Q$11) -> 23 | R21: =SUM(C21:Q21) -> 52 | S21: =COUNTIFS(Questions!$D$2:$D$458,$A21,Questions!$K$2:$K$458,"Assigned*") -> 2
A22: Total | C22: =SUM(C12:C21) -> 24 | D22: =SUM(D12:D21) -> 11 | E22: =SUM(E12:E21) -> 14 | F22: =SUM(F12:F21) -> 11 | G22: =SUM(G12:G21) -> 11 | H22: =SUM(H12:H21) -> 12 | I22: =SUM(I12:I21) -> 12 | J22: =SUM(J12:J21) -> 11 | ... S22: =SUM(S12:S21) -> 43

Sheet Questions
A1: ID | B1: Source | C1: Where in source | D1: Chapter | E1: Chapter name | F1: Topic | G1: Question type | H1: Question | I1: Answer choices | J1: Correct answer | K1: Answer from | L1: Explanation | M1: What it tests | N1: Note | O1: On the website as
A2: KH-02 | B2: Kahoot Ch 4-6 | C2: Q2 | D2: 4 | E2: The Flow of Food: An Introduction | F2: Preventing cross-contamination | G2: Multiple choice | H2: Using one set of cutting boards for raw poultry and another set of cutting boards for RTE food reduces the risk of | I2: A. cross-contamination. B. time-temperature abuse. C. physical contamination. D. toxic-metal poison | J2: A. cross-contamination. | K2: Source | L2: Separate cutting boards for raw poultry and ready-to-eat food keep pathogens from raw food from spreading to food that won’t be cooked. | M2: Link separate equipment to preventing cross-contamination. Time-temperature abuse and physical contamination are different hazards used as traps. | N2: Same question as MT-16. | O2: Multiple choice
A3: KH-03 | B3: Kahoot Ch 4-6 | C3: Q3 | D3: 4 | E3: The Flow of Food: An Introduction | F3: Temperature danger zone and time-temperature abuse | G3: Multiple choice | H3: Pathogens are likely to grow well in a meat stew that is | I3: A. below freezing temperature. B. at refrigeration temperatures. C. between 41°F and 135°F (5°C and 57°C). D. cooked to the correct internal temperature. | J3: C. between 41°F and 135°F (5°C and 57°C). | K3: Source | L3: Pathogens grow well between 41°F and 135°F (5°C and 57°C), the temperature danger zone. | M3: Recall the temperature danger zone, 41–135°F (5–57°C). Freezing, refrigeration and correct cooking all slow or stop growth. | O3: Multiple choice
A4: KH-04 | B4: Kahoot Ch 4-6 | C4: Q4 | D4: 4 | E4: The Flow of Food: An Introduction | F4: Thermometers and calibration | G4: Multiple choice | H4: What is the calibration nut on a bimetallic stemmed thermometer used for? | I4: A. To mark its sensing area B. To measure air temperature C. To keep it accurate D. To measure temperatures through glass | J4: C. To keep it accurate | K4: Source | L4: The calibration nut on a bimetallic stemmed thermometer is used to adjust it so its readings stay accurate. | M4: Know the parts of a bimetallic stemmed thermometer: the calibration nut keeps it accurate, while the dimple marks the sensing area (the trap). | O4: Multiple choice
A5: KH-05 | B5: Kahoot Ch 4-6 | C5: Q5 | D5: 4 | E5: The Flow of Food: An Introduction | F5: Thermometers and calibration | G5: Multiple choice | H5: Which probe should be used to check the temperature of a pork roast? | I5: A. Air B. Surface C. Immersion D. Penetration | J5: D. Penetration | K5: Source | L5: A penetration probe is used to check the internal temperature of thick food such as a roast. | M5: Match probe types to uses: penetration for thick food, immersion for liquids, surface for flat cooking equipment, air for coolers and ovens. | O5: Multiple choice
A6: KH-06 | B6: Kahoot Ch 4-6 | C6: Q6 | D6: 4 | E6: The Flow of Food: An Introduction | F6: Thermometers and calibration | G6: Multiple choice | H6: What do time-temperature indicators do? | I6: A. Measure temperature through a probe with a sensor at the end B. Measure the length of time that food should be cooked C. Show if food has been cross-contaminated during preparation D. Show if food has been time-temperature abused during shipment | J6: D. Show if food has been time-temperature abused during shipment | K6: Source | L6: Time-temperature indicators (TTIs) change color permanently if food has been time-temperature abused during shipment or storage. | M6: Know what a TTI does: shows past time-temperature abuse. It does not measure temperature through a probe or detect cross-contamination. | O6: Multiple choice
A7: KH-07 | B7: Kahoot Ch 4-6 | C7: Q7 | D7: 4 | E7: The Flow of Food: An Introduction | F7: Thermometers and calibration | G7: Multiple choice | H7: When using the ice-point method to calibrate a thermometer, to what temperature should the thermometer be adjusted? | I7: A. 32°F (0°C) B. 0°F (-18°C) C. 41°F (5°C) D. 212°F (100°C) | J7: A. 32°F (0°C) | K7: Source | L7: In the ice-point method, a thermometer in ice water is adjusted to read 32°F (0°C). | M7: Recall the ice-point calibration temperature, 32°F (0°C). 212°F (100°C) is the boiling-point method, and 41°F is the cold-holding limit. | O7: Multiple choice
A8: KH-09 | B8: Kahoot Ch 4-6 | C8: Q9 | D8: 5 | E8: The Flow of Food: Purchasing, Receiving, and Storage | F8: Approved suppliers and recalls | G8: Multiple choice | H8: What must a manager do with a recalled food item in the operation? | I8: A. Combine the item with non-recalled items during preparation B. Record the names of customers who purchase the item C. Store the recalled item separately from other food D. Sell all recalled items within 24 hours | J8: C. Store the recalled item separately from other food | K8: Source | L8: A recalled item must be stored separately from other food (and labeled) so it isn’t used or sold. | M8: Know the recall procedure: separate and label the item. Mixing it with other food, selling it quickly or tracking customers are the traps. | N8: Same question as DT-80. | O8: Multiple choice
A9: KH-10 | B9: Kahoot Ch 4-6 | C9: Q10 | D9: 5 | E9: The Flow of Food: Purchasing, Receiving, and Storage | F9: Receiving: packaging, documents and quality | G9: Multiple choice | H9: What are the packaging criteria for accepting nonfood items? | I9: A. Soiled but intact B. Clean and no more than two tears or punctures C. Soiled and no more than two tears or punctures D. Intact, clean, and protected from contamination | J9: D. Intact, clean, and protected from contamination | K9: Source | L9: Nonfood items must arrive in packaging that is intact, clean and protects them from contamination. | M9: Recall the packaging rule for nonfood items: intact and clean. Any soiled or torn packaging is grounds to reject. | O9: Multiple choice
A10: KH-11 | B10: Kahoot Ch 4-6 | C10: Q11 | D10: 5 | E10: The Flow of Food: Purchasing, Receiving, and Storage | F10: Storage temperature, rotation and order | G10: Multiple choice | H10: Supplies should be stored away from the walls and at least ________ off the floor. | I10: A. 2 inches (5 centimeters) B. 4 inches (10 centimeters) C. 5 inches (13 centimeters) D. 6 inches (15 centimeters) | J10: D. 6 inches (15 centimeters) | K10: Source | L10: Food and supplies must be stored away from walls and at least 6 inches (15 centimeters) off the floor. | M10: Recall the 6-inch (15 cm) rule for storage. Smaller distances are traps. | N10: Similar to DT-32. | O10: Multiple choice
A11: KH-12 | B11: Kahoot Ch 4-6 | C11: Q12 | D11: 5 | E11: The Flow of Food: Purchasing, Receiving, and Storage | F11: Labeling and date marking | G11: Multiple choice | H11: Ready-to-eat TCS food must be date marked if it will be held for longer than | I11: A. 12 hours. B. 24 hours. C. 36 hours. D. 48 hours. | J11: B. 24 hours. | K11: Source | L11: Ready-to-eat TCS food held for longer than 24 hours must be date-marked. | M11: Recall the 24-hour date-marking trigger. The other hour values are traps. | N11: Same question as MT-05; similar to DT-44. | O11: Multiple choice
A12: KH-13 | B12: Kahoot Ch 4-6 | C12: Q13 | D12: 5 | E12: The Flow of Food: Purchasing, Receiving, and Storage | F12: Storage temperature, rotation and order | G12: Multiple choice | H12: Which item is stored correctly in a cooler? | I12: A. Macaroni salad stored above raw salmon B. Raw ground pork stored below raw poultry C. Raw poultry stored above raw pork roast D. Sliced pineapple stored below raw steaks | J12: A. Macaroni salad stored above raw salmon | K12: Source | L12: Ready-to-eat food goes above raw food, and raw food is stored top to bottom by cooking temperature, with poultry on the bottom. | M12: Apply the cooler storage order. Each trap puts a raw item above something that should be higher, such as poultry above pork or raw steak over pineapple. | N12: Same question as MT-12. | O12: Multiple choice
A13: KH-14 | B13: Kahoot Ch 4-6 | C13: Q14 | D13: 5 | E13: The Flow of Food: Purchasing, Receiving, and Storage | F13: Receiving: packaging, documents and quality | G13: Multiple choice | H13: A food item that is received with an expired use-by date should be | I13: A. used immediately. B. accepted but labeled differently C. accepted but kept separate from other items. D. Rejected | J13: D. Rejected | K13: Source | L13: Food that arrives past its use-by or expiration date must be rejected. | M13: Know the receiving rule for expired dates: reject. Accepting it with a new label or keeping it separate are traps. | O13: Multiple choice
A14: KH-15 | B14: Kahoot Ch 4-6 | C14: Q15 | D14: 5 | E14: The Flow of Food: Purchasing, Receiving, and Storage | F14: Receiving temperatures | G14: Multiple choice | H14: Milk can be received at 45°F (7°C) under what conditions? | I14: A. It is thrown out after 2 days B. It is immediately cooled to 41°F (5°C) or lower C. It is cooled to 41°F (5°C) or lower in 4 hours D. It is served or used in the operation within 2 hours | J14: C. It is cooled to 41°F (5°C) or lower in 4 hours | K14: Source | L14: Milk may be received at 45°F (7°C) or lower, but must then be cooled to 41°F (5°C) or lower within four hours. | M14: Recall the milk receiving exception and its four-hour cooling window. Traps: cooling immediately, discarding after two days, or a two-hour use rule. | O14: Multiple choice
A15: KH-17 | B15: Kahoot Ch 4-6 | C15: Q17 | D15: 6 | E15: The Flow of Food: Preparation | F15: Prepping specific foods and variances | G15: Multiple choice | H15: Which food must be separated from ready-to-eat food? | I15: A. Raw nuts B. Hard cheeses C. Washed and peeled produce D. Unwashed fruits and vegetables | J15: D. Unwashed fruits and vegetables | K15: Source | L15: Unwashed fruits and vegetables can carry soil and pathogens, so they must be kept separate from ready-to-eat food. | M15: Know which produce needs separating: unwashed. Washed, peeled produce, hard cheese and raw nuts are not the cross-contamination risk here. | O15: Multiple choice
A16: KH-18 | B16: Kahoot Ch 4-6 | C16: Q18 | D16: 6 | E16: The Flow of Food: Preparation | F16: Prepping specific foods and variances | G16: Multiple choice | H16: A variance from the local regulatory authority is needed for | I16: A. smoking food to preserve it. B. developing a crisis-management plan. C. using TCS leftovers to make salads. D. using ice to cool food. | J16: A. smoking food to preserve it. | K16: Source | L16: A variance is required for special processes such as smoking food as a way to preserve it (not just for flavor). | M16: Recall which processes need a variance: smoking or curing to preserve, using additives, ROP, sprouting seeds and similar. Ice cooling and crisis plans don’t need one. | O16: Multiple choice
A17: KH-19 | B17: Kahoot Ch 4-6 | C17: Q19 | D17: 6 | E17: The Flow of Food: Preparation | F17: Thawing | G17: Multiple choice | H17: What is one way that food should NEVER be thawed? | I17: A. In a microwave B. In a cooler C. At room temperature D. As part of the cooking process | J17: C. At room temperature | K17: Source | L17: Food should never be thawed at room temperature because its surface sits in the temperature danger zone. | M17: Know the four safe thawing methods and spot the unsafe one: room temperature. Microwave, cooler and cooking are all approved. | O17: Multiple choice
A18: KH-20 | B18: Kahoot Ch 4-6 | C18: Q20 | D18: 6 | E18: The Flow of Food: Preparation | F18: Minimum internal cooking temperatures | G18: Multiple choice | H18: What is the required minimum internal cooking temperature for a chicken breast? | I18: A. 135°F (57°C) B. 145°F (63°C) for 15 seconds C. 155°F (68°C) for 17 seconds D. 165°F (74°C) for <1 second | J18: D. 165°F (74°C) for <1 second | K18: Source | L18: Poultry, including a chicken breast, must be cooked to 165°F (74°C) for less than 1 second (instantaneous). | M18: Recall the poultry cooking temperature, 165°F (74°C). 155°F is for ground meat and 145°F for seafood and whole cuts, which are the traps. | O18: Multiple choice
A19: KH-21 | B19: Kahoot Ch 4-6 | C19: Q21 | D19: 6 | E19: The Flow of Food: Preparation | F19: Cooling and reheating | G19: Multiple choice | H19: What temperature must soup that contains cooked beef be reheated to for hot holding? | I19: A. 135°F (57°C) for 15 seconds B. 145°F (63°C) for 15 seconds C. 155°F (68°C) for 15 seconds D. 165°F (74°C) for 15 seconds | J19: D. 165°F (74°C) for 15 seconds | K19: Source | L19: TCS food reheated for hot holding must reach 165°F (74°C) for 15 seconds within two hours, even though the beef was already cooked. | M19: Recall the reheating-for-hot-holding temperature: 165°F for 15 seconds. The trap is thinking cooked beef only needs its original cooking temperature. | N19: Similar to DT-41 and PT-23. | O19: Multiple choice
A20: KH-22 | B20: Kahoot Ch 4-6 | C20: Q22 | D20: 6 | E20: The Flow of Food: Preparation | F20: Consumer advisories and high-risk menus | G20: Multiple choice | H20: Which food item would the FDA advise against offering on a children's menu? | I20: A. Rare cheeseburgers B. Peanut butter and jelly sandwiches C. Cheese pizza D. Fried shrimp | J20: A. Rare cheeseburgers | K20: Source | L20: Operations serving high-risk groups such as young children should not offer raw or undercooked animal food, like rare burgers. | M20: Tests the high-risk population rule: no raw or undercooked meat on a children’s menu. PB&J and peanuts raise allergen questions, not undercooking. | O20: Multiple choice
A21: KH-23 | B21: Kahoot Ch 4-6 | C21: Q23 | D21: 6 | E21: The Flow of Food: Preparation | F21: Minimum internal cooking temperatures | G21: Multiple choice | H21: When checking the internal temperature of food, where should the thermometer be inserted? | I21: A. In the thinnest part of the food B. In the thickest part of the food C. On the bottom of the food D. On the top of the food | J21: B. In the thickest part of the food | K21: Source | L21: Insert the thermometer into the thickest part of the food, which is the last part to heat. | M21: Know where to take the temperature: the thickest part. Thinnest, top and bottom readings can be misleadingly high. | N21: Similar to DT-35 and MT-35. | O21: Multiple choice
A22: KH-24 | B22: Kahoot Ch 4-6 | C22: Q24 | D22: 6 | E22: The Flow of Food: Preparation | F22: Minimum internal cooking temperatures | G22: Multiple choice | H22: What is the required minimum internal cooking temperature for ground beef? | I22: A. 135°F (57°C) B. 145°F (63°C) for 15 seconds C. 155°F (68°C) for 17 seconds D. 165°F (74°C) for < 1 seconds | J22: C. 155°F (68°C) for 17 seconds | K22: Source | L22: Ground beef must be cooked to 155°F (68°C) for 17 seconds. | M22: Recall the ground meat cooking temperature, 155°F (68°C) for 17 seconds. 145°F is for whole cuts and 165°F for poultry. | N22: Similar to PT-17. | O22: Multiple choice
A23: KH-25 | B23: Kahoot Ch 4-6 | C23: Q25 | D23: 6 | E23: The Flow of Food: Preparation | F23: Thawing | G23: Multiple choice | H23: What must you do immediately after thawing food in a microwave? | I23: A. Cool it B. Cook it C. Hold it D. Freeze it | J23: B. Cook it | K23: Source | L23: Food thawed in a microwave must be cooked immediately afterward, because parts of it may have warmed into the danger zone. | M23: Know the microwave thawing rule: cook it right away. Holding, cooling or refreezing it are traps. | O23: Multiple choice
A24: KH-26 | B24: Kahoot Ch 4-6 | C24: Q26 | D24: 6 | E24: The Flow of Food: Preparation | F24: Consumer advisories and high-risk menus | G24: Multiple choice | H24: A consumer advisory should be provided for menu items that contain TCS food that | I24: A. is very spicy. B. contains gluten. C. is raw or undercooked. D. is made with a Big Nine allergen. | J24: C. is raw or undercooked. | K24: Source | L24: A consumer advisory is required when TCS food is served raw or undercooked. | M24: Recall the trigger for a consumer advisory: raw or undercooked TCS food. Allergens are handled by allergen notification, a different requirement. | N24: Similar to DT-51. | O24: Multiple choice
A25: KH-27 | B25: Kahoot Ch 4-6 | C25: Q27 | D25: 6 | E25: The Flow of Food: Preparation | F25: Cooling and reheating | G25: Multiple choice | H25: Food was cooled from 135°F to 70°F (57°C to 21°C) in 1 hour, then the food must cool from 70°F to 41°F (21°C to 5°C) within | I25: A. 4 hours B. 6 hours C. 2 hours D. 5 hours | J25: D. 5 hours | K25: Source | L25: Total cooling time is six hours, with no more than two for the first stage. If the first stage took one hour, five hours remain to reach 41°F (5°C). | M25: Apply the six-hour total: time saved in the first stage carries over to the second. The trap is assuming the second stage is always exactly four hours. | N25: Similar to DT-39. | O25: Multiple choice
A26: AQ01-01 | B26: SSM9E Activity Quiz 1 | C26: True or False #1 | D26: 1 | E26: Providing Safe Food | F26: How food becomes unsafe | G26: True / false | H26: A food handler’s hands can transfer pathogens from one food to another. | I26: A. True B. False | J26: True | K26: Source | L26: Hands that touch raw food, the body or dirty surfaces can carry pathogens to the next food they touch. | M26: Knowing that hands are a common route for moving pathogens between foods, which is why handwashing and glove changes matter. | O26: Multiple choice (rewritten)
A27: AQ01-02 | B27: SSM9E Activity Quiz 1 | C27: True or False #2 | D27: 1 | E27: Providing Safe Food | F27: How food becomes unsafe | G27: True / false | H27: Food handlers who don’t wash their hands correctly can cause a foodborne illness. | I27: A. True B. False | J27: True | K27: Source | L27: Pathogens on unwashed hands get into food and can make people sick. | M27: Linking poor personal hygiene, one of the ways food becomes unsafe, to actual illness. | O27: Multiple choice (rewritten)
A28: AQ01-03 | B28: SSM9E Activity Quiz 1 | C28: True or False #3 | D28: 1 | E28: Providing Safe Food | F28: Foodborne illness and high-risk groups | G28: True / false | H28: A foodborne-illness outbreak is when two or more people get sick after eating at the same place. | I28: A. True B. False | J28: False | K28: Source | L28: An outbreak is two or more people with the same symptoms after eating the same food, investigated and confirmed by regulators and lab analysis. | M28: Knowing the outbreak definition: the trap is “same place.” It takes two or more people with the same symptoms after eating the same food, confirmed by investigation. | O28: Multiple choice (rewritten)
A29: AQ01-04 | B29: SSM9E Activity Quiz 1 | C29: True or False #4 | D29: 1 | E29: Providing Safe Food | F29: Foodborne illness and high-risk groups | G29: True / false | H29: Adults are more likely than preschool-age children to get sick from contaminated food. | I29: A. True B. False | J29: False | K29: Source | L29: Preschool-age children are a high-risk population; healthy adults are not. | M29: Recognizing high-risk populations: preschool-age children are more likely to get sick because their immune systems are not fully developed. | O29: Multiple choice (rewritten)
A30: AQ01-05 | B30: SSM9E Activity Quiz 1 | C30: True or False #5 | D30: 1 | E30: Providing Safe Food | F30: Manager role, training and inspections | G30: True / false | H30: Training needs can be identified by watching employee performance. | I30: A. True B. False | J30: True | K30: Source | L30: Watching employees work (along with tests and inspection results) shows where training is needed. | M30: Knowing how managers find training needs: observing staff at work shows what they are doing wrong. | O30: Multiple choice (rewritten)
A31: AQ01-06 | B31: SSM9E Activity Quiz 1 | C31: How Food Becomes Unsafe #1 | D31: 1 | E31: Providing Safe Food | F31: How food becomes unsafe | G31: Multiple choice | H31: Leftover chili is cooled on the counter. How did the food become unsafe? | I31: A. Cross-contamination B. Poor personal hygiene C. Time-temperature abuse D. Poor cleaning and sanitizing | J31: C. Time-temperature abuse | K31: Source | L31: Food cooled on a counter does not pass through the temperature danger zone fast enough. | M31: Spotting time-temperature abuse: cooling at room temperature leaves food in the temperature danger zone too long. | O31: Multiple choice
A32: AQ01-07 | B32: SSM9E Activity Quiz 1 | C32: How Food Becomes Unsafe #2 | D32: 1 | E32: Providing Safe Food | F32: How food becomes unsafe | G32: Multiple choice | H32: A food handler wearing gloves places a chicken breast on the grill and then places lettuce and tomato on a bun. How did the food become unsafe? | I32: A. Cross-contamination B. Poor personal hygiene C. Time-temperature abuse D. Poor cleaning and sanitizing | J32: A. Cross-contamination | K32: Source | L32: Pathogens moved from the raw chicken to the lettuce and tomato on the same gloves; gloves must be changed between raw and ready-to-eat food. | M32: Recognizing cross-contamination: the same gloves carried pathogens from raw chicken to ready-to-eat produce. Gloves don’t help if they aren’t changed between tasks. | O32: Multiple choice
A33: AQ01-08 | B33: SSM9E Activity Quiz 1 | C33: How Food Becomes Unsafe #3 | D33: 1 | E33: Providing Safe Food | F33: How food becomes unsafe | G33: Multiple choice | H33: A food handler prepping a salad stops to scratch an itch on her arm and then returns to making the salad. How did the food become unsafe? | I33: A. Cross-contamination B. Poor personal hygiene C. Time-temperature abuse D. Poor cleaning and sanitizing | J33: B. Poor personal hygiene | K33: Source | L33: Touching skin can pick up pathogens; hands must be washed before going back to food. | M33: Recognizing poor personal hygiene: touching the body and then food without washing hands. | O33: Multiple choice
A34: AQ01-09 | B34: SSM9E Activity Quiz 1 | C34: How Food Becomes Unsafe #4 | D34: 1 | E34: Providing Safe Food | F34: How food becomes unsafe | G34: Multiple choice | H34: After prepping raw chicken on a cutting board, a food handler wipes the board with a towel and then uses it to slice tomatoes for a salad. How did the food become unsafe? | I34: A. Cross-contamination B. Poor personal hygiene C. Time-temperature abuse D. Poor cleaning and sanitizing | J34: D. Poor cleaning and sanitizing | K34: Source | L34: A food-contact surface must be cleaned and sanitized, not just wiped, between raw meat and ready-to-eat food. | M34: Telling poor cleaning and sanitizing apart from cross-contamination: the root problem is that wiping is not cleaning and sanitizing the board. | O34: Multiple choice
A35: AQ01-10 | B35: SSM9E Activity Quiz 1 | C35: How Food Becomes Unsafe #5 | D35: 1 | E35: Providing Safe Food | F35: Manager role, training and inspections | G35: Multiple choice | H35: What is the purpose of a regulatory health inspection? | I35: A. To certify employees in food handling procedures B. To ensure that an operation is meeting minimum food safety standards C. To rate the cleanliness of the establishment for public display D. To recognize establishments that exceed food safety expectations | J35: B. To ensure that an operation is meeting minimum food safety standards | K35: Source | L35: Regulatory inspections check that an operation meets the minimum standards of the food code. | M35: Knowing what inspections are for: checking that the operation meets minimum food safety standards, not certifying staff or rating the restaurant publicly. | O35: Multiple choice
A36: AQ01-11 | B36: SSM9E Activity Quiz 1 | C36: TCS Food | D36: 1 | E36: Providing Safe Food | F36: TCS and ready-to-eat food | G36: Select all that apply | H36: Which of these foods is, or contains, a TCS food? Select every one that applies. | I36: A. Baked potatoes B. Orange juice C. Pizza with diced tomatoes and green pepper D. Poached salmon E. Refried beans F. Scrambled shell eggs G. Shrimp fried rice H. Tofu ice cream I. Vanilla milk shake J. Whole-wheat bread | J36: A, C, D, E, F, G, H, I: Baked potatoes; Pizza with diced tomatoes and green pepper; Poached salmon; Refried beans; Scrambled shell eggs; Shrimp fried rice; Tofu ice cream; Vanilla milk shake | K36: Source | L36: TCS foods include cooked rice, potatoes and beans; cut tomatoes; seafood; eggs; tofu and soy protein; and milk and dairy products. | M36: Recognizing TCS foods: cooked starches and vegetables, cut tomatoes, fish, beans, eggs, rice, tofu and dairy all need time and temperature control. Orange juice and bread do not. | O36: Multiple choice (rewritten)
A37: AQ02-01 | B37: SSM9E Activity Quiz 2 | C37: True or False #1 | D37: 2 | E37: Forms of Contamination | F37: Pathogen growth (FAT TOM) | G37: True / false | H37: All pathogens need oxygen to grow. | I37: A. True B. False | J37: False | K37: Source | L37: Some pathogens need oxygen, but others grow without it (for example in reduced-oxygen packaging or cooked rice). | M37: Knowing the O in FAT TOM: some pathogens need oxygen and others grow without it. The trap is the word “all.” | O37: Multiple choice (rewritten)
... A42: AQ02-06 | B42: SSM9E Activity Quiz 2 | C42: True or False #6 | D42: 2 | E42: Forms of Contamination | F42: Food allergens and cross-contact | G42: True / false | H42: A restaurant must use table tents to notify people of the major allergens in their food. | I42: A. True B. False | J42: False | K42: Source | L42: Customers must be told about major allergens, but table tents are only one acceptable way to do it. | M42: Knowing that allergen notification can take several written forms (menus, placards, table tents, brochures); no single method is required. Watch for “must.” | O42: Multiple choice (rewritten)
A43: AQ02-07 | B43: SSM9E Activity Quiz 2 | C43: Pathogen Growth | D43: 2 | E43: Forms of Contamination | F43: Pathogen growth (FAT TOM) | G43: List | H43: List the six conditions that pathogens need to grow. | J43: Food; Acidity; Temperature; Time; Oxygen; Moisture | K43: Source | L43: FAT TOM: Food, Acidity, Temperature, Time, Oxygen, Moisture. | M43: Recalling FAT TOM, the six conditions that let pathogens grow, which are also the levers used to control them. | O43: Knowledge point
A44: AQ02-08 | B44: SSM9E Activity Quiz 2 | C44: Pathogens and Linked Food #1 | D44: 2 | E44: Forms of Contamination | F44: Big Six pathogens and linked foods | G44: Select all that apply | H44: Which foods are commonly linked with Hepatitis A? Select every one that applies. | I44: A. Beverages B. Eggs and poultry C. Meat D. Fish E. Shellfish F. Ready-to-eat food G. Produce H. Rice/grains I. Milk/dairy products J. Contaminated water | J44: E, F, J: Shellfish; Ready-to-eat food; Contaminated water | K44: Source | L44: Hepatitis A is linked with ready-to-eat food, shellfish from contaminated water, and contaminated water. | M44: Matching Hepatitis A to its foods: shellfish from contaminated water, ready-to-eat food and contaminated water. It spreads through feces on hands, so RTE food is key. | O44: Multiple choice (rewritten)
...

Sheet Assigned answers
A1: ID | B1: Source | C1: Where in source | D1: Chapter | E1: Chapter name | F1: Topic | G1: Question type | H1: Question | I1: Answer choices | J1: Correct answer | K1: Answer from | L1: Explanation | M1: What it tests | N1: Note | O1: On the website as
A2: MT-09 | B2: Mock ServSafe Test | C2: Q9 | D2: 1 | E2: Providing Safe Food | F2: Manager role, training and inspections | G2: Multiple choice | H2: A manager can ensure employees are following their training by | I2: A. reviewing the most current regulatory inspection report. B. having them complete a written assessment. C. asking them if they can do what they were trained to do. D. monitoring them. | J2: D. monitoring them. | K2: Assigned (high confidence) | L2: Managers make sure training is followed by monitoring employees. DT-11 asks the same question and its key answer is “monitoring them.” | M2: Knowing that monitoring confirms employees follow their training. Asking them or giving a written test only checks what they say or know, not what they do. | N2: Same question as DT-11. | O2: Multiple choice
A3: MT-21 | B3: Mock ServSafe Test | C3: Q21 | D3: 2 | E3: Forms of Contamination | F3: Big Six pathogens and linked foods | G3: Multiple choice | H3: Unpasteurized dairy products are commonly linked with what type of food? | I3: A. Listeria B. Bacillus cereus C. Salmonella Typhi D. Vibrio vulnificus | J3: A. Listeria | K3: Assigned (high confidence) | L3: Listeria monocytogenes is linked with unpasteurized dairy products, raw meat and ready-to-eat deli food. | M3: Linking pathogens to foods: Listeria with unpasteurized dairy. Bacillus cereus is best known for cooked rice dishes, Salmonella Typhi for ready-to-eat food and beverages, and Vibrio vulnificus for raw oysters. | N3: The question says “what type of food” but means which pathogen; all four options are pathogens. | O3: Multiple choice
A4: MT-22 | B4: Mock ServSafe Test | C4: Q22 | D4: 6 | E4: The Flow of Food: Preparation | F4: Cooling and reheating | G4: Multiple choice | H4: Which TCS food is being cooled correctly? | I4: A. Chicken pot pie is placed in a freezer. B. A beef roast is loosely covered and placed on the top shelf in the cooler. C. Minestrone soup is stirred with an ice paddle D. A tofu stir fry is covered tightly and placed outside in the winter. | J4: C. Minestrone soup is stirred with an ice paddle | K4: Assigned (high confidence) | L4: Stirring with an ice paddle is an approved cooling method. Freezers and coolers are not designed to cool hot food quickly, and leaving food outside is not controlled cooling. | M4: Knowing the approved cooling methods: ice-water bath, ice paddle, blast chiller, or adding ice as an ingredient. Putting hot food in a freezer or cooler alone is the trap. | O4: Multiple choice
A5: MT-25 | B5: Mock ServSafe Test | C5: Q25 | D5: 8 | E5: Food Safety Management Systems | F5: Food safety culture and active managerial control | G5: Multiple choice | H5: Three components of active managerial control include | I5: A. identifying risks, record keeping, and training. B. identifying risks, creating purchase orders, and training. C. identifying risks, creating specifications, and training. D. identifying risks, corrective action, and training. | J5: D. identifying risks, corrective action, and training. | K5: Assigned (high confidence) | L5: The six steps of active managerial control are identifying risks, monitoring, corrective action, management oversight, training and re-evaluation. Record keeping, purchase orders and specifications are not among them. | M5: Recalling the steps of active managerial control. Record keeping is a HACCP principle, and purchase orders or specifications are purchasing tasks. | O5: Multiple choice
A6: MT-33 | B6: Mock ServSafe Test | C6: Q33 | D6: 9 | E6: Safe Facilities and Pest Management | F6: Lighting, ventilation, garbage and wastewater | G6: Multiple choice | H6: Outdoor garbage containers must be | I6: A. washed frequently. B. kept away from customer parking areas. C. lined with plastic or wet-strength paper. D. kept covered with tight-fitting lids. | J6: D. kept covered with tight-fitting lids. | K6: Assigned (high confidence) | L6: Outdoor garbage containers must have tight-fitting lids and be kept covered. DT-74 asks the same thing and its key is “kept covered at all times.” | M6: Recalling the rules for outdoor garbage containers: tight-fitting lids, kept covered, on a smooth, durable surface. Distance from customer parking is not a requirement. | N6: Similar to DT-74. | O6: Multiple choice
A7: MT-34 | B7: Mock ServSafe Test | C7: Q34 | D7: 2 | E7: Forms of Contamination | F7: Viruses, parasites, fungi and biological toxins | G7: Multiple choice | H7: Domoic acid is a toxin found in shellfish from the Pacific Northwest and causes which illness? | I7: A. Ciguatera fish poisoning B. Amnesic shellfish poisoning (ASP) C. Scrombroid poisoning D. Paralytic shellfish poisoning (PSP) | J7: B. Amnesic shellfish poisoning (ASP) | K7: Assigned (high confidence) | L7: Domoic acid causes amnesic shellfish poisoning (ASP). Paralytic shellfish poisoning (PSP) is caused by a different toxin (saxitoxin). | M7: Matching shellfish toxins to illnesses: domoic acid causes amnesic shellfish poisoning. PSP is the close look-alike; ciguatera and scombroid poisoning come from finfish. | O7: Multiple choice
A8: MT-38 | B8: Mock ServSafe Test | C8: Q38 | D8: 5 | E8: The Flow of Food: Purchasing, Receiving, and Storage | F8: Receiving: packaging, documents and quality | G8: Multiple choice | H8: How long must shellstock tags be kept on file? | I8: A. 90 days after the last shellfish was sold or served from the container B. 30 days after the last shellfish was sold or served from the container C. 30 days after the day the shellfish were received | J8: A. 90 days after the last shellfish was sold or served from the container | K8: Assigned (high confidence) | L8: Shellstock tags must be kept for 90 days from the date the last shellfish was sold or served from the container. PT-38 also keys 90 days. | M8: Recalling both parts of the tag rule: 90 days, counted from when the last shellfish in the container was used, not from receiving. | N8: Similar to PT-38. | O8: Multiple choice
A9: MT-42 | B9: Mock ServSafe Test | C9: Q42 | D9: 7 | E9: The Flow of Food: Service | F9: Serving food safely | G9: Multiple choice | H9: A customer returns a carryout container to a restaurant to be refilled with food. It looks clean, but they will not refill it. Is the restaurant correct to refuse? | I9: A. No, because the container was made to hold food. B. No, because the container can be refilled for personal consumption. C. Yes, because the container is a single-service container that is not designed to be refilled. D. Yes, because the container may not have been appropriately cleaned and sanitized. | J9: C. Yes, because the container is a single-service container that is not designed to be refilled. | K9: Assigned (high confidence) | L9: Single-service containers are not designed to be reused, so they cannot be refilled. DT-09 asks the same question and its key is the single-service answer. | M9: Knowing single-service containers can never be refilled, however clean they look. The trap gives a sensible-sounding reason (it may not be sanitized) that isn’t the rule. | N9: Same question as DT-09. | O9: Multiple choice
A10: MT-46 | B10: Mock ServSafe Test | C10: Q46 | D10: 6 | E10: The Flow of Food: Preparation | F10: Minimum internal cooking temperatures | G10: Multiple choice | H10: A lamb roast must be cooked to an internal temperature of | I10: A. 145°F (63°C) for 4 minutes B. 155°F (68°C) for 17 seconds C. 145°F (63°C) for 15 seconds D. 135°F (57°C) with no minimum time | J10: A. 145°F (63°C) for 4 minutes | K10: Assigned (high confidence) | L10: Roasts of beef, pork, veal and lamb must be cooked to 145°F (63°C) for 4 minutes. | M10: Separating roasts (145°F for 4 minutes) from steaks and chops (145°F for 15 seconds), which is the trap the test-taker fell for. | O10: Multiple choice
A11: MT-48 | B11: Mock ServSafe Test | C11: Q48 | D11: 6 | E11: The Flow of Food: Preparation | F11: Cooling and reheating | G11: Multiple choice | H11: Which TCS food has been cooled correctly? | I11: A. Barbeque jackfruit cooled from 135°F to 70°F (57°C to 21°C) in three hours and then from 70°F to 41°F (21°C to 5°C) in two hours B. Corn chowder cooled from 135°F to 70°F (57°C to 21°C) in one hour and then from 70°F to 41°F (21°C to 5°C) in five hours C. Beef brisket cooled from 135°F to 70°F (57°C to 21°C) in two hours and then from 70°F to 41°F (21°C to 5°C) in six hours D. Oyster stuffing cooled from 135°F to 70°F (57°C to 21°C) in one hour and then from 70°F to 41°F (21°C to 5°C) in four hours | J11: B. Corn chowder cooled from 135°F to 70°F (57°C to 21°C) in one hour and then from 70°F to 41°F (21°C to 5°C) in five hours | K11: Assigned (medium confidence) | L11: Two-stage cooling allows 2 hours to reach 70°F (21°C) and 6 hours in total. The corn chowder took 1 hour, then 5 hours: 6 hours in total. | M11: Applying two-stage cooling: 2 hours or less to reach 70°F, 6 hours or less in total. When the first stage finishes early, the leftover time carries into the second stage. | N11: As written, option D (1 hour, then 4 hours) also meets the rule. The attempt marked D wrong, so the quiz’s intended answer is B, which uses the full 6 hours. | O11: Multiple choice
A12: RD-004 | B12: Review Slide Deck | C12: Slide 4 | D12: 1 | E12: Providing Safe Food | F12: How food becomes unsafe | G12: Multiple choice | H12: What is the problem shown in the picture? (The slide’s picture isn’t in the file.) | I12: A. Time-temperature abuse B. Cross-contamination C. Poor personal hygiene D. Poor cleaning and sanitizing | J12: Can’t be determined: the slide’s picture isn’t in the file | K12: Not answerable (picture missing) | L12: The four practices that make food unsafe are time-temperature abuse, cross-contamination, poor personal hygiene, and poor cleaning and sanitizing; which one applies depends on the picture. | M12: Recognizing which of the four practices that make food unsafe is happening in a situation. | O12: Not on the website (picture missing)
A13: RD-005 | B13: Review Slide Deck | C13: Slide 5 | D13: 1 | E13: Providing Safe Food | F13: How food becomes unsafe | G13: Multiple choice | H13: What is the problem shown in the picture? (The slide’s picture isn’t in the file.) | I13: A. Time-temperature abuse B. Cross-contamination C. Poor personal hygiene D. Poor cleaning and sanitizing | J13: Can’t be determined: the slide’s picture isn’t in the file | K13: Not answerable (picture missing) | L13: The four practices that make food unsafe are time-temperature abuse, cross-contamination, poor personal hygiene, and poor cleaning and sanitizing; which one applies depends on the picture. | M13: Recognizing which of the four practices that make food unsafe is happening in a situation. | O13: Not on the website (picture missing)
A14: RD-006 | B14: Review Slide Deck | C14: Slide 6 | D14: 1 | E14: Providing Safe Food | F14: How food becomes unsafe | G14: Multiple choice | H14: Between uses, a food handler just wipes the prep table with a single-use towel. What is the problem? | I14: A. Time-temperature abuse B. Cross-contamination C. Poor personal hygiene D. Poor cleaning and sanitizing | J14: D. Poor cleaning and sanitizing | K14: Assigned (medium confidence) | L14: Wiping is not cleaning and sanitizing: a food-contact surface must be cleaned, rinsed, and sanitized between uses, so this is poor cleaning and sanitizing. | M14: Telling poor cleaning and sanitizing apart from cross-contamination: the fault here is the missing clean-and-sanitize step, not raw food touching ready-to-eat food. | O14: Multiple choice
A15: RD-007 | B15: Review Slide Deck | C15: Slide 7 | D15: 1 | E15: Providing Safe Food | F15: TCS and ready-to-eat food | G15: Multiple choice | H15: Does cut lettuce need time and temperature control to keep it safe? | I15: A. Yes B. No | J15: A. Yes | K15: Assigned (high confidence) | L15: Cut leafy greens are TCS food and must be held at 41°F (5°C) or lower. | M15: Knowing that cutting changes some produce into TCS food: whole lettuce doesn’t need temperature control, but cut leafy greens do. | O15: Multiple choice
A16: RD-022 | B16: Review Slide Deck | C16: Slide 22 | D16: 2 | E16: Forms of Contamination | F16: Viruses, parasites, fungi and biological toxins | G16: Multiple choice | H16: What is the onset time for an illness from a biological toxin? | I16: A. Within a few minutes B. Within a few hours C. 6–12 hours D. 24 hours | J16: A. Within a few minutes | K16: Assigned (medium confidence) | L16: Illness from biological toxins (such as seafood toxins) usually starts within minutes of eating the food, though it varies by toxin. | M16: Knowing that toxin illnesses start fast, usually within minutes, unlike many bacterial and viral illnesses that take hours or days. | O16: Multiple choice
A17: RD-023 | B17: Review Slide Deck | C17: Slide 23 | D17: 2 | E17: Forms of Contamination | F17: Viruses, parasites, fungi and biological toxins | G17: Select all that apply | H17: Which symptoms are associated with illness from a biological toxin? Select all that apply. | I17: A. Vomiting and diarrhea B. Neurological symptoms C. Flushing, hives, and difficulty breathing D. Heart palpitations | J17: A, B, C, D: Vomiting and diarrhea; Neurological symptoms; Flushing, hives, and difficulty breathing; Heart palpitations | K17: Assigned (medium confidence) | L17: Depending on the toxin, symptoms can include vomiting or diarrhea, neurological symptoms (such as tingling), flushing, hives, difficulty breathing, and heart palpitations. | M17: Knowing the range of toxin symptoms, especially the neurological ones and flushing or hives, which aren’t typical of other foodborne illnesses. | N17: The slide lists the options without saying which are correct; all four are recognized symptoms. | O17: Multiple choice (rewritten)
A18: RD-029 | B18: Review Slide Deck | C18: Slide 29 | D18: 3 | E18: The Safe Food Handler | F18: Handwashing and hand care | G18: Multiple choice | H18: What should the temperature of the water be when you first wet your hands and when you rinse the soap off? | I18: A. Cold B. Warm C. As cold as you can stand D. As hot as you can stand | J18: B. Warm | K18: Assigned (high confidence) | L18: ServSafe’s handwashing steps (9th edition) say to wet and rinse hands and arms with warm running water. | M18: Recalling the handwashing steps: warm running water to wet and rinse, not the extremes. | O18: Multiple choice
A19: RD-037 | B19: Review Slide Deck | C19: Slide 37 | D19: 3 | E19: The Safe Food Handler | F19: Reporting illness, restricting and excluding | G19: Multiple choice | H19: Does a chef need to tell you if they have been diagnosed with an illness from Shigella spp.? | I19: A. Yes B. No | J19: A. Yes | K19: Assigned (high confidence) | L19: Food handlers must report a diagnosis of an illness caused by any of the Big Six pathogens, including Shigella spp., to the manager. | M19: Knowing that a Big Six diagnosis must always be reported to the manager. | O19: Multiple choice
A20: RD-038 | B20: Review Slide Deck | C20: Slide 38 | D20: 3 | E20: The Safe Food Handler | F20: Reporting illness, restricting and excluding | G20: Multiple choice | H20: Does a cook need to tell you if they live with someone diagnosed with hepatitis A? | I20: A. Yes B. No | J20: A. Yes | K20: Assigned (high confidence) | L20: Food handlers must tell the manager if they have been exposed to, or live with someone diagnosed with, an illness caused by a Big Six pathogen such as hepatitis A. | M20: Knowing that exposure counts too: living with someone diagnosed with a Big Six illness must be reported, even if the cook feels fine. | O20: Multiple choice
A21: RD-039 | B21: Review Slide Deck | C21: Slide 39 | D21: 3 | E21: The Safe Food Handler | F21: Reporting illness, restricting and excluding | G21: Multiple choice | H21: Do you have to report a food handler diagnosed with norovirus to the health department? | I21: A. Yes B. No | J21: A. Yes | K21: Assigned (high confidence) | L21: Managers must notify the regulatory authority when a food handler is diagnosed with an illness caused by a Big Six pathogen, such as norovirus. | M21: Knowing which cases go beyond the manager to the regulatory authority: Big Six diagnoses (and jaundice) must be reported. | O21: Multiple choice
A22: RD-041 | B22: Review Slide Deck | C22: Slide 41 | D22: 3 | E22: The Safe Food Handler | F22: Reporting illness, restricting and excluding | G22: Multiple choice | H22: A food handler has an infected wound that is not covered properly. Restrict or exclude? | I22: A. Restrict from working with exposed food, utensils, and equipment B. Exclude from the operation | J22: A. Restrict from working with exposed food, utensils, and equipment | K22: Assigned (high confidence) | L22: A food handler with an infected wound or boil that isn’t properly covered must be restricted from working with exposed food, utensils, and equipment. | M22: Knowing that an uncovered infected wound calls for restriction (keep away from food), not exclusion from the operation. | O22: Multiple choice
A23: RD-042 | B23: Review Slide Deck | C23: Slide 42 | D23: 3 | E23: The Safe Food Handler | F23: Reporting illness, restricting and excluding | G23: Multiple choice | H23: A food handler at a restaurant has a sore throat with fever. Restrict or exclude? | I23: A. Restrict from working with exposed food, utensils, and equipment B. Exclude from the operation | J23: A. Restrict from working with exposed food, utensils, and equipment | K23: Assigned (high confidence) | L23: Sore throat with fever means restricting the food handler; exclusion applies only when the operation primarily serves a high-risk population. | M23: Applying the sore-throat-with-fever rule: restrict at a regular restaurant, exclude only where a high-risk population is served. | O23: Multiple choice
A24: RD-043 | B24: Review Slide Deck | C24: Slide 43 | D24: 3 | E24: The Safe Food Handler | F24: Reporting illness, restricting and excluding | G24: Multiple choice | H24: A food handler has a persistent runny nose. Restrict or exclude? | I24: A. Restrict from working with exposed food, utensils, and equipment B. Exclude from the operation | J24: A. Restrict from working with exposed food, utensils, and equipment | K24: Assigned (high confidence) | L24: Persistent sneezing, coughing, or a runny nose that causes discharges means restricting the food handler from working with exposed food, utensils, and equipment. | M24: Knowing that persistent respiratory symptoms lead to restriction, not exclusion. | O24: Multiple choice
A25: RD-044 | B25: Review Slide Deck | C25: Slide 44 | D25: 3 | E25: The Safe Food Handler | F25: Reporting illness, restricting and excluding | G25: Multiple choice | H25: A food handler is vomiting. Restrict or exclude? | I25: A. Restrict from working with exposed food, utensils, and equipment B. Exclude from the operation | J25: B. Exclude from the operation | K25: Assigned (high confidence) | L25: Vomiting (like diarrhea) means the food handler must be excluded from the operation. | M25: Knowing that vomiting and diarrhea always mean exclusion, the stricter of the two actions. | O25: Multiple choice
A26: RD-045 | B26: Review Slide Deck | C26: Slide 45 | D26: 3 | E26: The Safe Food Handler | F26: Reporting illness, restricting and excluding | G26: Multiple choice | H26: When can food handlers who are vomiting return to work? | I26: A. When they have had no symptoms for at least 24 hours B. When they have a written release from a medical practitioner C. Either A or B | J26: C. Either A or B | K26: Assigned (high confidence) | L26: Food handlers excluded for vomiting or diarrhea can return when they have had no symptoms for at least 24 hours or have a written release from a medical practitioner. | M26: Knowing the return-to-work rule for vomiting: either 24 symptom-free hours or a medical release is enough. | O26: Multiple choice
A27: RD-046 | B27: Review Slide Deck | C27: Slide 46 | D27: 3 | E27: The Safe Food Handler | F27: Reporting illness, restricting and excluding | G27: Multiple choice | H27: When can food handlers who have jaundice return to work? | I27: A. When they have a written release from a medical practitioner B. When they have approval from the health department C. Both A and B | J27: C. Both A and B | K27: Assigned (high confidence) | L27: A food handler with jaundice is excluded and reported, and can return only with approval from the regulatory authority and a written release from a medical practitioner. | M27: Contrasting jaundice with vomiting: jaundice needs both a medical release and regulatory approval, not just one. | O27: Multiple choice
A28: RD-047 | B28: Review Slide Deck | C28: Slide 47 | D28: 3 | E28: The Safe Food Handler | F28: Reporting illness, restricting and excluding | G28: Multiple choice | H28: A food handler has been diagnosed with an illness caused by hepatitis A. What must a manager do? | I28: A. Restrict the food handler from working with exposed food, utensils, and equipment B. Exclude the food handler from the operation | J28: B. Exclude the food handler from the operation | K28: Assigned (high confidence) | L28: A food handler diagnosed with hepatitis A must be excluded from the operation, and the regulatory authority must be notified. | M28: Knowing that a Big Six diagnosis such as hepatitis A means exclusion, not just restriction. | O28: Multiple choice
A29: RD-055 | B29: Review Slide Deck | C29: Slide 55 | D29: 4 | E29: The Flow of Food: An Introduction | F29: Thermometers and calibration | G29: Select all that apply | H29: Which thermometer(s) should be used to check a hamburger patty? Select all that apply. | I29: A. Bimetallic stemmed B. Thermocouple C. Infrared | J29: B: Thermocouple | K29: Assigned (high confidence) | L29: A thin food like a hamburger patty needs a thermocouple or thermistor with a thin probe; a bimetallic stemmed thermometer’s sensing area is too long for thin food, and infrared thermometers only read the surface. | M29: Matching thermometer to food thickness, and knowing infrared can’t measure internal temperature. | O29: Multiple choice (rewritten)
